<?xml version="1.0" encoding="utf-8"?>
<!-- This URDF was automatically created by SolidWorks to URDF Exporter and then extended for ROS/Gazebo simulation. -->
<robot name="R1">
  <link name="base_link">
    <inertial>
      <origin xyz="0.02 0.0 0.12" rpy="0 0 0" />
      <mass value="38.0603057004842" />
      <inertia
        ixx="0.70"
        ixy="0.0"
        ixz="0.0"
        iyy="1.10"
        iyz="0.0"
        izz="0.95" />
    </inertial>
    <visual>
      <origin xyz="0 0 0" rpy="0 0 3.14159265359" />
      <geometry>
        <mesh filename="package://zebrat/urdf/meshes/base_link.stl" />
      </geometry>
      <material name="">
        <color rgba="0.792156862745098 0.819607843137255 0.933333333333333 1" />
      </material>
    </visual>
    <collision>
      <origin xyz="0.02 0 0.17" rpy="0 0 0" />
      <geometry>
        <box size="0.50 0.16 0.22" />
      </geometry>
    </collision>
  </link>

  <link name="front_left_steering_link">
    <inertial>
      <origin xyz="0 0 -0.020375" rpy="0 0 0" />
      <mass value="0.30" />
      <inertia ixx="2e-4" ixy="0" ixz="0" iyy="2e-4" iyz="0" izz="2e-4" />
    </inertial>
  </link>

  <link name="front_right_steering_link">
    <inertial>
      <origin xyz="0 0 -0.020375" rpy="0 0 0" />
      <mass value="0.30" />
      <inertia ixx="2e-4" ixy="0" ixz="0" iyy="2e-4" iyz="0" izz="2e-4" />
    </inertial>
  </link>

  <link name="Empty_Link1">
    <inertial>
      <origin xyz="0 0 0" rpy="0 0 0" />
      <mass value="0.102007563940439" />
      <inertia
        ixx="6.03197633111551E-05"
        ixy="-1.09650777535302E-10"
        ixz="7.71132214702415E-10"
        iyy="9.37857965039355E-05"
        iyz="9.81331506021422E-10"
        izz="6.03194335121187E-05" />
    </inertial>
    <visual>
      <origin xyz="0 0 0" rpy="1.57079632679 0 0" />
      <geometry>
        <cylinder radius="0.04075" length="0.040" />
      </geometry>
      <material name="">
        <color rgba="0.152941176470588 0.152941176470588 0.152941176470588 1" />
      </material>
    </visual>
    <collision>
      <origin xyz="0 0 0" rpy="1.57079632679 0 0" />
      <geometry>
        <cylinder radius="0.04075" length="0.040" />
      </geometry>
    </collision>
  </link>

  <joint name="front_left_steering_joint" type="revolute">
    <origin xyz="0.220127909860013 0.142085316479216 0.04075" rpy="0 0 0" />
    <parent link="base_link" />
    <child link="front_left_steering_link" />
    <axis xyz="0 0 1" />
    <limit lower="-0.6" upper="0.6" effort="30" velocity="4" />
    <dynamics damping="3.0" friction="0.2" />
  </joint>

  <joint name="front_left_wheel_joint" type="continuous">
    <origin xyz="0 0 -0.04075" rpy="0 0 0" />
    <parent link="front_left_steering_link" />
    <child link="Empty_Link1" />
    <axis xyz="0 1 0" />
    <limit effort="30" velocity="60" />
    <dynamics damping="0.02" friction="0.0" />
  </joint>

  <link name="Empty_Link2">
    <inertial>
      <origin xyz="0 0 0" rpy="0 0 0" />
      <mass value="0.102007476255524" />
      <inertia
        ixx="6.03196775650763E-05"
        ixy="-1.30454716001587E-10"
        ixz="8.2130239199344E-10"
        iyy="9.37857280988688E-05"
        iyz="9.77509097955072E-10"
        izz="6.03194264639649E-05" />
    </inertial>
    <visual>
      <origin xyz="0 0 0" rpy="1.57079632679 0 0" />
      <geometry>
        <cylinder radius="0.04075" length="0.040" />
      </geometry>
      <material name="">
        <color rgba="0.152941176470588 0.152941176470588 0.152941176470588 1" />
      </material>
    </visual>
    <collision>
      <origin xyz="0 0 0" rpy="1.57079632679 0 0" />
      <geometry>
        <cylinder radius="0.04075" length="0.040" />
      </geometry>
    </collision>
  </link>

  <joint name="front_right_steering_joint" type="revolute">
    <origin xyz="0.220127909860013 -0.122535316479216 0.04075" rpy="0 0 0" />
    <parent link="base_link" />
    <child link="front_right_steering_link" />
    <axis xyz="0 0 1" />
    <limit lower="-0.6" upper="0.6" effort="30" velocity="4" />
    <dynamics damping="3.0" friction="0.2" />
  </joint>

  <joint name="front_right_wheel_joint" type="continuous">
    <origin xyz="0 0 -0.04075" rpy="0 0 0" />
    <parent link="front_right_steering_link" />
    <child link="Empty_Link2" />
    <axis xyz="0 -1 0" />
    <limit effort="30" velocity="60" />
    <dynamics damping="0.02" friction="0.0" />
  </joint>

  <link name="Empty_Link3">
    <inertial>
      <origin xyz="3.76217621722574E-07 -0.00343116064614217 1.77734477486638E-07" rpy="0 0 0" />
      <mass value="0.130385211409052" />
      <inertia
        ixx="7.86812106003073E-05"
        ixy="5.53858346756479E-11"
        ixz="9.23581794342341E-08"
        iyy="0.000108048071855382"
        iyz="-1.15152881530515E-10"
        izz="7.82862361574103E-05" />
    </inertial>
    <visual>
      <origin xyz="0 -0.0010 0" rpy="1.57079632679 0 0" />
      <geometry>
        <cylinder radius="0.04075" length="0.0465" />
      </geometry>
      <material name="">
        <color rgba="0.152941176470588 0.152941176470588 0.152941176470588 1" />
      </material>
    </visual>
    <collision>
      <origin xyz="0 -0.0010 0" rpy="1.57079632679 0 0" />
      <geometry>
        <cylinder radius="0.04075" length="0.0465" />
      </geometry>
    </collision>
  </link>

  <joint name="rear_right_wheel_joint" type="continuous">
    <origin xyz="-0.19879978611665 -0.122535316479219 0.0" rpy="0 0 0" />
    <parent link="base_link" />
    <child link="Empty_Link3" />
    <axis xyz="0 -1 0" />
    <limit effort="20" velocity="20" />
    <dynamics damping="0.02" friction="0.0" />
  </joint>

  <link name="Empty_Link4">
    <inertial>
      <origin xyz="3.64091904681008E-07 0.000181544843160394 3.71723492477368E-07" rpy="0 0 0" />
      <mass value="0.130386181839137" />
      <inertia
        ixx="7.86817593166718E-05"
        ixy="7.73070482159629E-11"
        ixz="9.25265700656962E-08"
        iyy="0.00010804820646223"
        iyz="-1.16088106414147E-10"
        izz="7.82861601090754E-05" />
    </inertial>
    <visual>
      <origin xyz="0 -0.0020 0" rpy="1.57079632679 0 0" />
      <geometry>
        <cylinder radius="0.04075" length="0.0465" />
      </geometry>
      <material name="">
        <color rgba="0.152941176470588 0.152941176470588 0.152941176470588 1" />
      </material>
    </visual>
    <collision>
      <origin xyz="0 -0.0020 0" rpy="1.57079632679 0 0" />
      <geometry>
        <cylinder radius="0.04075" length="0.0465" />
      </geometry>
    </collision>
  </link>

  <joint name="rear_left_wheel_joint" type="continuous">
    <origin xyz="-0.19879978611665 0.119285316479219 0.0" rpy="0 0 0" />
    <parent link="base_link" />
    <child link="Empty_Link4" />
    <axis xyz="0 1 0" />
    <limit effort="20" velocity="20" />
    <dynamics damping="0.02" friction="0.0" />
  </joint>

  <link name="imu_link">
    <inertial>
      <origin xyz="0 0 0" rpy="0 0 0" />
      <mass value="0.01" />
      <inertia ixx="1e-5" ixy="0" ixz="0" iyy="1e-5" iyz="0" izz="1e-5" />
    </inertial>
  </link>

  <joint name="imu_joint" type="fixed">
    <origin xyz="0.02 0 0.22" rpy="0 0 0" />
    <parent link="base_link" />
    <child link="imu_link" />
  </joint>

  <link name="laser_link">
    <inertial>
      <origin xyz="0 0 0" rpy="0 0 0" />
      <mass value="0.05" />
      <inertia ixx="2e-5" ixy="0" ixz="0" iyy="2e-5" iyz="0" izz="2e-5" />
    </inertial>
  </link>

  <joint name="laser_joint" type="fixed">
    <origin xyz="0.34 0 0.36" rpy="0 0 0" />
    <parent link="base_link" />
    <child link="laser_link" />
  </joint>

  <link name="camera_link">
    <inertial>
      <origin xyz="0 0 0" rpy="0 0 0" />
      <mass value="0.05" />
      <inertia ixx="2e-5" ixy="0" ixz="0" iyy="2e-5" iyz="0" izz="2e-5" />
    </inertial>
  </link>

  <joint name="camera_joint" type="fixed">
    <origin xyz="0.30 0 0.28" rpy="0 0 0" />
    <parent link="base_link" />
    <child link="camera_link" />
  </joint>

  <link name="camera_optical_link" />

  <joint name="camera_optical_joint" type="fixed">
    <origin xyz="0 0 0" rpy="-1.57079632679 0 -1.57079632679" />
    <parent link="camera_link" />
    <child link="camera_optical_link" />
  </joint>

  <gazebo reference="base_link">
    <material>Gazebo/White</material>
    <mu1>0.8</mu1>
    <mu2>0.8</mu2>
    <slip1>0.10</slip1>
    <slip2>0.10</slip2>
    <kp>30000.0</kp>
    <kd>5.0</kd>
  </gazebo>

  <gazebo reference="front_left_steering_link">
    <material>Gazebo/Black</material>
  </gazebo>

  <gazebo reference="front_right_steering_link">
    <material>Gazebo/Black</material>
  </gazebo>

  <gazebo reference="Empty_Link1">
    <material>Gazebo/Black</material>
    <mu1>4.0</mu1>
    <mu2>4.0</mu2>
    <fdir1>1 0 0</fdir1>
    <slip1>0.05</slip1>
    <slip2>0.05</slip2>
    <kp>50000.0</kp>
    <kd>5.0</kd>
  </gazebo>

  <gazebo reference="Empty_Link2">
    <material>Gazebo/Black</material>
    <mu1>4.0</mu1>
    <mu2>4.0</mu2>
    <fdir1>1 0 0</fdir1>
    <slip1>0.05</slip1>
    <slip2>0.05</slip2>
    <kp>50000.0</kp>
    <kd>5.0</kd>
  </gazebo>

  <gazebo reference="Empty_Link3">
    <material>Gazebo/Black</material>
    <mu1>4.0</mu1>
    <mu2>4.0</mu2>
    <fdir1>1 0 0</fdir1>
    <slip1>0.05</slip1>
    <slip2>0.05</slip2>
    <kp>50000.0</kp>
    <kd>5.0</kd>
  </gazebo>

  <gazebo reference="Empty_Link4">
    <material>Gazebo/Black</material>
    <mu1>4.0</mu1>
    <mu2>4.0</mu2>
    <fdir1>1 0 0</fdir1>
    <slip1>0.05</slip1>
    <slip2>0.05</slip2>
    <kp>50000.0</kp>
    <kd>5.0</kd>
  </gazebo>

  <gazebo reference="laser_link">
    <sensor name="front_laser" type="ray">
      <always_on>true</always_on>
      <update_rate>15.0</update_rate>
      <visualize>true</visualize>
      <pose>0 0 0 0 0 0</pose>
      <ray>
        <scan>
          <horizontal>
            <samples>720</samples>
            <resolution>1</resolution>
            <min_angle>-2.35619</min_angle>
            <max_angle>2.35619</max_angle>
          </horizontal>
        </scan>
        <range>
          <min>0.12</min>
          <max>8.0</max>
          <resolution>0.01</resolution>
        </range>
        <noise>
          <type>gaussian</type>
          <mean>0.0</mean>
          <stddev>0.01</stddev>
        </noise>
      </ray>
      <plugin name="laser_plugin" filename="libgazebo_ros_laser.so">
        <topicName>scan</topicName>
        <frameName>laser_link</frameName>
      </plugin>
    </sensor>
  </gazebo>

  <gazebo reference="imu_link">
    <sensor name="imu_sensor" type="imu">
      <always_on>true</always_on>
      <update_rate>50.0</update_rate>
      <plugin name="imu_plugin" filename="libgazebo_ros_imu_sensor.so">
        <alwaysOn>true</alwaysOn>
        <bodyName>imu_link</bodyName>
        <topicName>imu/data</topicName>
        <frameName>imu_link</frameName>
        <gaussianNoise>0.002</gaussianNoise>
      </plugin>
    </sensor>
  </gazebo>

  <gazebo reference="camera_link">
    <sensor name="front_camera" type="depth">
      <always_on>true</always_on>
      <update_rate>15.0</update_rate>
      <visualize>false</visualize>
      <camera>
        <horizontal_fov>1.3962634</horizontal_fov>
        <image>
          <width>640</width>
          <height>480</height>
          <format>R8G8B8</format>
        </image>
        <clip>
          <near>0.05</near>
          <far>20.0</far>
        </clip>
        <depth_camera />
      </camera>
      <plugin name="camera_plugin" filename="libgazebo_ros_openni_kinect.so">
        <alwaysOn>true</alwaysOn>
        <updateRate>15.0</updateRate>
        <baseline>0.2</baseline>
        <cameraName>front_camera</cameraName>
        <imageTopicName>rgb/image_raw</imageTopicName>
        <cameraInfoTopicName>rgb/camera_info</cameraInfoTopicName>
        <depthImageTopicName>depth/image_raw</depthImageTopicName>
        <depthImageCameraInfoTopicName>depth/camera_info</depthImageCameraInfoTopicName>
        <pointCloudTopicName>depth/points</pointCloudTopicName>
        <frameName>camera_optical_link</frameName>
        <hackBaseline>0.07</hackBaseline>
        <pointCloudCutoff>0.10</pointCloudCutoff>
        <pointCloudCutoffMax>8.0</pointCloudCutoffMax>
        <distortionK1>0.0</distortionK1>
        <distortionK2>0.0</distortionK2>
        <distortionK3>0.0</distortionK3>
        <distortionT1>0.0</distortionT1>
        <distortionT2>0.0</distortionT2>
        <CxPrime>0.0</CxPrime>
        <Cx>0.0</Cx>
        <Cy>0.0</Cy>
        <focalLength>0.0</focalLength>
      </plugin>
    </sensor>
  </gazebo>

  <transmission name="front_left_steering_transmission">
    <type>transmission_interface/SimpleTransmission</type>
    <joint name="front_left_steering_joint">
      <hardwareInterface>hardware_interface/PositionJointInterface</hardwareInterface>
    </joint>
    <actuator name="front_left_steering_motor">
      <mechanicalReduction>1</mechanicalReduction>
      <hardwareInterface>hardware_interface/PositionJointInterface</hardwareInterface>
    </actuator>
  </transmission>

  <transmission name="front_right_steering_transmission">
    <type>transmission_interface/SimpleTransmission</type>
    <joint name="front_right_steering_joint">
      <hardwareInterface>hardware_interface/PositionJointInterface</hardwareInterface>
    </joint>
    <actuator name="front_right_steering_motor">
      <mechanicalReduction>1</mechanicalReduction>
      <hardwareInterface>hardware_interface/PositionJointInterface</hardwareInterface>
    </actuator>
  </transmission>

  <transmission name="front_left_wheel_transmission">
    <type>transmission_interface/SimpleTransmission</type>
    <joint name="front_left_wheel_joint">
      <hardwareInterface>hardware_interface/VelocityJointInterface</hardwareInterface>
    </joint>
    <actuator name="front_left_wheel_motor">
      <mechanicalReduction>1</mechanicalReduction>
      <hardwareInterface>hardware_interface/VelocityJointInterface</hardwareInterface>
    </actuator>
  </transmission>

  <transmission name="front_right_wheel_transmission">
    <type>transmission_interface/SimpleTransmission</type>
    <joint name="front_right_wheel_joint">
      <hardwareInterface>hardware_interface/VelocityJointInterface</hardwareInterface>
    </joint>
    <actuator name="front_right_wheel_motor">
      <mechanicalReduction>1</mechanicalReduction>
      <hardwareInterface>hardware_interface/VelocityJointInterface</hardwareInterface>
    </actuator>
  </transmission>

  <transmission name="rear_left_wheel_transmission">
    <type>transmission_interface/SimpleTransmission</type>
    <joint name="rear_left_wheel_joint">
      <hardwareInterface>hardware_interface/EffortJointInterface</hardwareInterface>
    </joint>
    <actuator name="rear_left_wheel_passive">
      <mechanicalReduction>1</mechanicalReduction>
      <hardwareInterface>hardware_interface/EffortJointInterface</hardwareInterface>
    </actuator>
  </transmission>

  <transmission name="rear_right_wheel_transmission">
    <type>transmission_interface/SimpleTransmission</type>
    <joint name="rear_right_wheel_joint">
      <hardwareInterface>hardware_interface/EffortJointInterface</hardwareInterface>
    </joint>
    <actuator name="rear_right_wheel_passive">
      <mechanicalReduction>1</mechanicalReduction>
      <hardwareInterface>hardware_interface/EffortJointInterface</hardwareInterface>
    </actuator>
  </transmission>

  <gazebo>
    <plugin name="ground_truth_odom" filename="libgazebo_ros_p3d.so">
      <alwaysOn>true</alwaysOn>
      <updateRate>50.0</updateRate>
      <bodyName>base_link</bodyName>
      <topicName>ground_truth_odom</topicName>
      <frameName>world</frameName>
      <localTwist>true</localTwist>
      <xyzOffset>0 0 0</xyzOffset>
      <rpyOffset>0 0 0</rpyOffset>
      <gaussianNoise>0.0</gaussianNoise>
    </plugin>
  </gazebo>

  <gazebo>
    <plugin name="gazebo_ros_control" filename="libgazebo_ros_control.so">
      <robotNamespace>/r1</robotNamespace>
      <robotParam>/robot_description_gazebo</robotParam>
      <robotSimType>gazebo_ros_control/DefaultRobotHWSim</robotSimType>
    </plugin>
  </gazebo>
</robot>
